Workbook

Sheet README
C16: Company: Apple Inc
C17: Prepared By: Kieran O'Connell
C18: Purpose: Financial Modeling and Valuation Analysis

Sheet IS_BS
A1: Income Statement: Apple Inc | D1: Other Inputs:
A2: Item | B2: 2024 | D2: Number of Common Shares (millions) | E2: 15408
A3: Net Sales | B3: 391035 | D3: Dividends per share | E3: 0.98
A4: Costs(Except Depr) | B4: 256374 | D4: Tax Rate | E4: 0.241
A5: Deprecation | B5: 11445 | D5: Wacc | E5: =_xlfn.XLOOKUP(TRIM(SP!E58),SP!E55:E57,SP!F55:F57) -> 0.08 | F5: (Assumed)
A6: Total Operating Costs | B6: =B4+B5 -> 267819
A7: EBIT | B7: =B3-B6 -> 123216
A8: Other Income/Expense, (net) | B8: =B9-B7 -> 269
A9: Earning before taxes | B9: 123485
A10: Taxes (24.1%) | B10: =B9*24.1% -> 29759.885
A11: Net Income | B11: =B9-B10 -> 93725.115
A13: Balance Sheet : Apple Inc
A14: Item | B14: 2024
A15: Cash | B15: 29943
A16: Marketable Securities | B16: 35228
A17: Accounts recieveable | B17: 33410
A18: Vendor receievables | B18: 32833
A19: Inventories | B19: 7286
A20: Other Current Assets | B20: 14287
A21: Total Current Assets | B21: =SUM(B15:B20) -> 152987
A22: Net PPE | B22: 45680
A23: Marketable Securities | B23: 91479
A24: Other non-current assets | B24: 74834
A25: Total Assets: | B25: =B21+SUM(B22:B24) -> 364980
A27: Current Liabilities:
A28: Accounts Payable | B28: 68960
A29: Other current liabilities | B29: 78304
A30: Deferred Revenue | B30: 8249
A31: Commercial paper | B31: 9967
A32: Term Debt | B32: 10912
A33: Total current liabilities | B33: =SUM(B28:B32) -> 176392
A34: Non-current liabilties:
A35: Term Debt | B35: 85750
A36: Other non-current liabilities | B36: 45888
A37: Total liabilities | B37: =B33+SUM(B35:B36) -> 308030
A39: Shareholders Equity | B39: 56950
A40: Liabilities + Shareholders Equity | B40: =B39+B37 -> 364980

Sheet SP
A2: Operating Balance sheet | B2: Actual | C2: Projected | D2: Projected | E2: Projected | F2: Projected
B3: 2024 | C3: 2025 | D3: 2026 | E3: 2027 | F3: 2028
A4: Net Sales | B4: 391035 | C4: 410587 | D4: 431116 | E4: 452672 | F4: 475306 | G4: >5% growth assumed, apple historicall has 2-6%
A5: Costs (except depreciation) | B5: 256374 | C5: 269193 | D5: 282653 | E5: 296786 | F5: 311625
A6: Depreciation | B6: 11445 | C6: 12318 | D6: 12933 | E6: 13580 | F6: 14259 | G6: > Assumed 3% of sales
A7: Total operating costs | B7: 267819 | C7: 281511 | D7: 295586 | E7: 310366 | F7: 325884
A8: Earnings before interest & tax | B8: 123216 | C8: 129076 | D8: 135530 | E8: 142306 | F8: 149422
A11: Operating Balance sheet | B11: Actual | C11: Projected | D11: Projected | E11: Projected | F11: Projected
A12: Operating Assets | B12: 2024 | C12: 2025 | D12: 2026 | E12: 2027 | F12: 2028
A13: Accounts receivable | B13: 33410 | C13: 35096 | D13: 36851 | E13: 38694 | F13: 40629
A14: Vendor receivables | B14: 32833 | C14: 34474 | D14: 36198 | E14: 38008 | F14: 39908
A15: Inventories | B15: 7286 | C15: 7800 | D15: 8190 | E15: 8600 | F15: 9030
A16: Net plant and equipment | B16: 45680 | C16: 48762 | D16: 51200 | E16: 53760 | F16: 56448
A18: Operating Liabilities | B18: Actual | C18: Projected | D18: Projected | E18: Projected | F18: Projected
A19: Operating Liabilities | B19: 2024 | C19: 2025 | D19: 2026 | E19: 2027 | F19: 2028
A20: Accounts Payable | B20: 68960 | C20: 72851 | D20: 76493 | E20: 80318 | F20: 84334
A21: Accruals (Other current liabilities) | B21: 78304 | C21: 82219 | D21: 86330 | E21: 90646 | F21: 95178
A22: Deferred revenue | B22: 8249 | C22: 8662 | D22: 9095 | E22: 9550 | F22: 10028
A25: Calculation of FCF | B25: =B11 -> Actual | C25: =C11 -> Projected | D25: =D11 -> Projected | E25: =E11 -> Projected | F25: =F11 -> Projected
B26: =B12 -> 2024 | C26: =C12 -> 2025 | D26: =D12 -> 2026 | E26: =E12 -> 2027 | F26: =F12 -> 2028
A27: Operating current assets | B27: =B13+B14+B15 -> 73529 | C27: =C13+C14+C15 -> 77370 | D27: =D13+D14+D15 -> 81239 | E27: =E13+E14+E15 -> 85302 | F27: =F13+F14+F15 -> 89567
A28: Operating current liabilities | B28: =B20+B21+B22 -> 155513 | C28: =C20+C21+C22 -> 163732 | D28: =D20+D21+D22 -> 171918 | E28: =E20+E21+E22 -> 180514 | F28: =F20+F21+F22 -> 189540
A29: Net operating working capital | B29: =B27-B28 -> -81984 | C29: =C27-C28 -> -86362 | D29: =D27-D28 -> -90679 | E29: =E27-E28 -> -95212 | F29: =F27-F28 -> -99973
A30: Net PPE | B30: {=B16:F16} -> 45680 | C30: 48762 | D30: 51200 | E30: 53760 | F30: 56448
A31: Net operatimg capital | B31: =B29+B30 -> -36304 | C31: =C29+C30 -> -37600 | D31: =D29+D30 -> -39479 | E31: =E29+E30 -> -41452 | F31: =F29+F30 -> -43525
A32: Nopat | B32: =B8*(1-24.1%) -> 93520.944 | C32: =C8*(1-24.1%) -> 97968.684 | D32: =D8*(1-24.1%) -> 102867.27 | E32: =E8*(1-24.1%) -> 108010.25 | F32: =F8*(1-24.1%) -> 113411.3
A33: Investment in Operating capital | C33: =C31-B31 -> -1296 | D33: =D31-C31 -> -1879 | E33: =E31-D31 -> -1973 | F33: =F31-E31 -> -2073
A34: FCF | C34: =C32-C33 -> 99264.684 | D34: =D32-D33 -> 104746.27 | E34: =E32-E33 -> 109983.25 | F34: =F32-F33 -> 115484.3
B36: {=B25:F26} -> Actual | C36: Projected | D36: Projected | E36: Projected | F36: Projected
B37: 2024 | C37: 2025 | D37: 2026 | E37: 2027 | F37: 2028
A38: ROIC | C38: =C32/(B30) -> 2.1446735 | D38: =D32/(C30) -> 2.1095786 | E38: =E32/(D30) -> 2.1095753 | F38: =F32/(E30) -> 2.1095852
A39: WACC | C39: =IS_BS!$E$5 -> 0.08 | D39: =IS_BS!$E$5 -> 0.08 | E39: =IS_BS!$E$5 -> 0.08 | F39: =IS_BS!$E$5 -> 0.08
A40: Spread | C40: =C38-C39 -> 2.0646735 | D40: =D38-D39 -> 2.0295786 | E40: =E38-E39 -> 2.0295753 | F40: =F38-F39 -> 2.0295852
A43: Value of Operations | B43: {=_xlfn.ANCHORARRAY(B36)} -> Actual | C43: Projected | D43: Projected | E43: Projected | F43: Projected
B44: 2024 | C44: 2025 | D44: 2026 | E44: 2027 | F44: 2028
A45: Long-term constant growth in FCF | F45: =_xlfn.XLOOKUP(TRIM(E58), $E$55:$E$57, $G$55:$G$57) -> 0.045
A46: VALUATION
A47: Free cash flow | C47: {=C34:F34} -> 99264.684 | D47: 104746.27 | E47: 109983.25 | F47: 115484.3
A48: Horizon Value | F48: =F47*(1+F45)/(F39-F45) -> 3448031.2
A49: FCF + Horizon Value | C49: =SUM(C47:C48) -> 99264.684 | D49: =SUM(D47:D48) -> 104746.27 | E49: =SUM(E47:E48) -> 109983.25 | F49: =SUM(F47:F48) -> 3563515.5
...
